Workbook

Sheet MAIN
A1: Space Exploration Technologies Corp. (NASDAQ: SPCX)
A2: Sum-of-the-parts discounted cash flow | Connectivity and Space modelled; AI implied
B3: Company | C3: Space Exploration Technologies Corp. | F3: Current Stock Price | G3: =Assumptions!$C$18 -> 151.97 | I3: Perpetuity | J3: Exit Multiple | K3: Average
B4: Balance sheet date | C4: 46203 | F4: Diluted S/O | G4: =Assumptions!$C$17 -> 13.176 | H4: Implied Price - Connectivity | I4: =DCF!C26 -> 13.215067 | J4: =DCF!E26 -> 13.509431 | K4: =AVERAGE(I4, J4) -> 13.362249
B5: Currency | C5: USD | F5: MKT cap | G5: =Assumptions!$C$18*Assumptions!$C$17 -> 2002.3567 | H5: vs share price - Connectivity only | I5: =I4/$G$3-1 -> -0.9130416 | J5: =J4/G3-1 -> -0.91110462 | K5: =AVERAGE(I5, J5) -> -0.91207311
B6: Units | C6: b | F6: Net Cash | G6: =Assumptions!$C$16 -> 60.645
B7: Prepared by | C7: Aleem | F7: EV - Connectivity only | G7: =DCF!$C$22 -> 113.47673
B9: Segment | C9: Enterprise value ($B) | D9: Perpetuity ($B) | E9: Exit multiple ($B)
B10: Connectivity (Starlink) | C10: 115.4 | D10: 113.5 | E10: 117.4
B11: Space (launch) | C11: 8 | D11: 7.9 | E11: 8
B12: AI (not modelled) | C12: n/a
B13: Total modelled enterprise value | C13: =SUM(C10:C11) -> 123.4
B14: Net cash | C14: =Assumptions!$C$16 -> 60.645
B15: Equity value, modelled segments | C15: =C13+C14 -> 184.045
B16: Diluted shares (bn) | C16: =Assumptions!$C$17 -> 13.176
B17: Value per share, modelled segments | C17: =C15/C16 -> 13.9682
B18: Share price | C18: =Assumptions!$C$18 -> 151.97
B19: Modelled segments as % of share price | C19: =C17/C18 -> 0.091914192
A21: IMPLIED VALUE OF THE AI SEGMENT
B22: Market capitalisation | C22: =Assumptions!$C$17*Assumptions!$C$18 -> 2002.3567
B23: Less: net cash | C23: =-Assumptions!$C$16 -> -60.645
B24: Market-implied enterprise value | C24: =C22+C23 -> 1941.7117
B25: Less: modelled enterprise value | C25: =-C13 -> -123.4
B26: Implied enterprise value, AI segment | C26: =C24+C25 -> 1818.3117
B27: As % of market-implied enterprise value | C27: =C26/C24 -> 0.93644783
B28: Implied multiple of FY2025A AI revenue | C28: =C26/'Revenue Build'!C29 -> 568.0449
B29: Live EV check | C29: =AVERAGE(DCF!$C$22,DCF!$E$22) -> 115.416

Sheet Assumptions
A1: SPCX - DCF Assumptions
A2: US$ billions unless noted. Fiscal year ends December 31.
A3: Segment being valued (1 = Connectivity, 2 = Space) | C3: 1
A4: Live drivers (feed the DCF) | C4: FY2025A | D4: FY2026E | E4: FY2027E | F4: FY2028E | G4: FY2029E | H4: FY2030E
A5: Revenue Growth (%) | D5: =CHOOSE($C$3,'Revenue Build'!D18,'Revenue Build'!D26) -> 0.47782559 | E5: =CHOOSE($C$3,'Revenue Build'!E18,'Revenue Build'!E26) -> 0.37948657 | F5: =CHOOSE($C$3,'Revenue Build'!F18,'Revenue Build'!F26) -> 0.26130783 | G5: =CHOOSE($C$3,'Revenue Build'!G18,'Revenue Build'!G26) -> 0.18377049 | H5: =CHOOSE($C$3,'Revenue Build'!H18,'Revenue Build'!H26) -> 0.14433596
A6: Operating Margin % | C6: =IF(CHOOSE($C$3,C23,C31)="","",CHOOSE($C$3,C23,C31)) -> 0.3884254 | D6: =IF(CHOOSE($C$3,D23,D31)="","",CHOOSE($C$3,D23,D31)) -> 0.38 | E6: =IF(CHOOSE($C$3,E23,E31)="","",CHOOSE($C$3,E23,E31)) -> 0.4 | F6: =IF(CHOOSE($C$3,F23,F31)="","",CHOOSE($C$3,F23,F31)) -> 0.42 | G6: =IF(CHOOSE($C$3,G23,G31)="","",CHOOSE($C$3,G23,G31)) -> 0.43 | H6: =IF(CHOOSE($C$3,H23,H31)="","",CHOOSE($C$3,H23,H31)) -> 0.44
A7: CapEx % of Revenue | C7: =IF(CHOOSE($C$3,C24,C32)="","",CHOOSE($C$3,C24,C32)) -> 0.36690963 | D7: =IF(CHOOSE($C$3,D24,D32)="","",CHOOSE($C$3,D24,D32)) -> 0.38 | E7: =IF(CHOOSE($C$3,E24,E32)="","",CHOOSE($C$3,E24,E32)) -> 0.34 | F7: =IF(CHOOSE($C$3,F24,F32)="","",CHOOSE($C$3,F24,F32)) -> 0.3 | G7: =IF(CHOOSE($C$3,G24,G32)="","",CHOOSE($C$3,G24,G32)) -> 0.27 | H7: =IF(CHOOSE($C$3,H24,H32)="","",CHOOSE($C$3,H24,H32)) -> 0.25
A8: D&A % of Revenue | C8: =IF(CHOOSE($C$3,C25,C33)="","",CHOOSE($C$3,C25,C33)) -> 0.20593659 | D8: =IF(CHOOSE($C$3,D25,D33)="","",CHOOSE($C$3,D25,D33)) -> 0.21 | E8: =IF(CHOOSE($C$3,E25,E33)="","",CHOOSE($C$3,E25,E33)) -> 0.215 | F8: =IF(CHOOSE($C$3,F25,F33)="","",CHOOSE($C$3,F25,F33)) -> 0.22 | G8: =IF(CHOOSE($C$3,G25,G33)="","",CHOOSE($C$3,G25,G33)) -> 0.22 | H8: =IF(CHOOSE($C$3,H25,H33)="","",CHOOSE($C$3,H25,H33)) -> 0.22
A10: Single Value Asumptions | C10: Value
A11: Revenue Base Year ($B) | C11: =CHOOSE($C$3,'Revenue Build'!C17,'Revenue Build'!C25) -> 11.387
A12: Effective Tax Rate | C12: 0.2
A13: Change in WC (% of Change in Revenue) | C13: 0.09
A14: Terminal Growth Rate | C14: 0.025
A15: Exit EV/EBITDA multiple | C15: =CHOOSE($C$3,C27,C35) -> 6
A16: Net Cash ($B) | C16: =93.522+6.487-39.364 -> 60.645
A17: Diluted Shares (bn) | C17: 13.176
A18: Current Share Price ($) | C18: 151.97
A22: CONNECTIVITY - segment drivers | C22: FY2025A | D22: FY2026E | E22: FY2027E | F22: FY2028E | G22: FY2029E | H22: FY2030E
A23: Operating margin % | C23: ='EBITDA Recon'!C19 -> 0.3884254 | D23: 0.38 | E23: 0.4 | F23: 0.42 | G23: 0.43 | H23: 0.44
A24: CapEx % of revenue | C24: ='EBITDA Recon'!C23 -> 0.36690963 | D24: 0.38 | E24: 0.34 | F24: 0.3 | G24: 0.27 | H24: 0.25
A25: D&A % of revenue | C25: ='EBITDA Recon'!C21 -> 0.20593659 | D25: 0.21 | E25: 0.215 | F25: 0.22 | G25: 0.22 | H25: 0.22
A26: Levered beta | C26: 1.2
A27: Exit EV/EBITDA multiple | C27: 6
A30: SPACE - segment drivers | C30: FY2025A | D30: FY2026E | E30: FY2027E | F30: FY2028E | G30: FY2029E | H30: FY2030E
A31: Operating margin % | C31: ='EBITDA Recon'!B19 -> -0.16079295 | D31: -0.407 | E31: -0.076 | F31: 0.184 | G31: 0.306 | H31: 0.368
A32: CapEx % of revenue | C32: ='EBITDA Recon'!B23 -> 0.93783651 | D32: 0.85 | E32: 0.68 | F32: 0.5 | G32: 0.34 | H32: 0.24
A33: D&A % of revenue | C33: ='EBITDA Recon'!B21 -> 0.19823789 | D33: 0.21 | E33: 0.22 | F33: 0.23 | G33: 0.23 | H33: 0.24
A34: Levered beta | C34: 1.45
A35: Exit EV/EBITDA multiple | C35: 5
A37: Beta and exit multiple are selected by the segment switch in C3.

Sheet Revenue Build
A1: Space Exploration Technologies Corp (SPCX) - Segment Revenue Build
A2: Three stacked segments, each tying to a disclosed FY2025A total. BLUE = disclosed actual. YELLOW = your forecast input (left blank on purpose). Black = formula.
A4: US$ billions unless noted | B4: Units | C4: FY2025A | D4: FY2026E | E4: FY2027E | F4: FY2028E | G4: FY2029E | H4: FY2030E
A6: CONNECTIVITY - ties to FY2025A $11.387B
A7: Subscribers, end of period | B7: millions | C7: 8.9 | D7: 15 | E7: 20.5 | F7: 25.3 | G7: 29.3 | H7: 32.5
A8: y/y growth in subscribers | B8: % | D8: =IF(OR(C7="",D7=""),"",D7/C7-1) -> 0.68539326 | E8: =IF(OR(D7="",E7=""),"",E7/D7-1) -> 0.36666667 | F8: =IF(OR(E7="",F7=""),"",F7/E7-1) -> 0.23414634 | G8: =IF(OR(F7="",G7=""),"",G7/F7-1) -> 0.15810277 | H8: =IF(OR(G7="",H7=""),"",H7/G7-1) -> 0.10921502
A9: Subscribers, FY2024A year-end (anchor for FY2025 average) | B9: millions | C9: 4.4
A10: Average subscribers | B10: millions | C10: =AVERAGE(C9,C7) -> 6.65 | D10: =IF(OR(C7="",D7=""),"",AVERAGE(C7,D7)) -> 11.95 | E10: =IF(OR(D7="",E7=""),"",AVERAGE(D7,E7)) -> 17.75 | F10: =IF(OR(E7="",F7=""),"",AVERAGE(E7,F7)) -> 22.9 | G10: =IF(OR(F7="",G7=""),"",AVERAGE(F7,G7)) -> 27.3 | H10: =IF(OR(G7="",H7=""),"",AVERAGE(G7,H7)) -> 30.9
A11: ARPU (Consumer service only) | B11: $/month | C11: 81 | D11: 65 | E11: 62 | F11: 60 | G11: 58 | H11: 57
A12: y/y change in ARPU | B12: % | D12: =IF(OR(C11="",D11=""),"",D11/C11-1) -> -0.19753086 | E12: =IF(OR(D11="",E11=""),"",E11/D11-1) -> -0.046153846 | F12: =IF(OR(E11="",F11=""),"",F11/E11-1) -> -0.032258065 | G12: =IF(OR(F11="",G11=""),"",G11/F11-1) -> -0.033333333 | H12: =IF(OR(G11="",H11=""),"",H11/G11-1) -> -0.017241379
A13: Consumer subscription revenue | B13: $B | C13: =C10*C11*12/1000 -> 6.4638 | D13: =IF(OR(D10="",D11=""),"",D10*D11*12/1000) -> 9.321 | E13: =IF(OR(E10="",E11=""),"",E10*E11*12/1000) -> 13.206 | F13: =IF(OR(F10="",F11=""),"",F10*F11*12/1000) -> 16.488 | G13: =IF(OR(G10="",G11=""),"",G10*G11*12/1000) -> 19.0008 | H13: =IF(OR(H10="",H11=""),"",H10*H11*12/1000) -> 21.1356
A14: Consumer revenue as disclosed (FY2025A only) | B14: $B | C14: 7.208
A15: Consumer hardware (Starlink Kits) | B15: $B | C15: =C14-C13 -> 0.7442 | D15: 1.007 | E15: 0.908 | F15: 0.792 | G15: 0.66 | H15: 0.528
A16: Enterprise & Government (incl. Starlink Mobile) | B16: $B | C16: 4.179 | D16: 6.5 | E16: 9.1 | F16: 12 | G16: 15 | H16: 18
A17: CONNECTIVITY revenue | B17: $B | C17: =C13+C15+C16 -> 11.387 | D17: =IF(OR(D13="",D15="",D16=""),"",D13+D15+D16) -> 16.828 | E17: =IF(OR(E13="",E15="",E16=""),"",E13+E15+E16) -> 23.214 | F17: =IF(OR(F13="",F15="",F16=""),"",F13+F15+F16) -> 29.28 | G17: =IF(OR(G13="",G15="",G16=""),"",G13+G15+G16) -> 34.6608 | H17: =IF(OR(H13="",H15="",H16=""),"",H13+H15+H16) -> 39.6636
A18: implied y/y growth | B18: % | D18: =IF(OR(C17="",D17=""),"",D17/C17-1) -> 0.47782559 | E18: =IF(OR(D17="",E17=""),"",E17/D17-1) -> 0.37948657 | F18: =IF(OR(E17="",F17=""),"",F17/E17-1) -> 0.26130783 | G18: =IF(OR(F17="",G17=""),"",G17/F17-1) -> 0.18377049 | H18: =IF(OR(G17="",H17=""),"",H17/G17-1) -> 0.14433596
A20: SPACE - ties to FY2025A $4.086B
A21: External launches (third-party customers only) | B21: count | C21: 43 | D21: 34 | E21: 40 | F21: 48 | G21: 56 | H21: 64
A22: Price per external launch | B22: $mm | C22: =2576/C21 -> 59.906977 | D22: 60 | E22: 62 | F22: 64 | G22: 66 | H22: 68
A23: Launch Services revenue | B23: $B | C23: =C21*C22/1000 -> 2.576 | D23: =IF(OR(D21="",D22=""),"",D21*D22/1000) -> 2.04 | E23: =IF(OR(E21="",E22=""),"",E21*E22/1000) -> 2.48 | F23: =IF(OR(F21="",F22=""),"",F21*F22/1000) -> 3.072 | G23: =IF(OR(G21="",G22=""),"",G21*G22/1000) -> 3.696 | H23: =IF(OR(H21="",H22=""),"",H21*H22/1000) -> 4.352
A24: Launch & Development revenue | B24: $B | C24: 1.51 | D24: 1.65 | E24: 1.85 | F24: 2.1 | G24: 2.35 | H24: 2.6
A25: SPACE revenue | B25: $B | C25: =C23+C24 -> 4.086 | D25: =IF(OR(D23="",D24=""),"",D23+D24) -> 3.69 | E25: =IF(OR(E23="",E24=""),"",E23+E24) -> 4.33 | F25: =IF(OR(F23="",F24=""),"",F23+F24) -> 5.172 | G25: =IF(OR(G23="",G24=""),"",G23+G24) -> 6.046 | H25: =IF(OR(H23="",H24=""),"",H23+H24) -> 6.952
A26: implied y/y growth | B26: % | D26: =IF(OR(C25="",D25=""),"",D25/C25-1) -> -0.0969163 | E26: =IF(OR(D25="",E25=""),"",E25/D25-1) -> 0.17344173 | F26: =IF(OR(E25="",F25=""),"",F25/E25-1) -> 0.19445727 | G26: =IF(OR(F25="",G25=""),"",G25/F25-1) -> 0.16898685 | H26: =IF(OR(G25="",H25=""),"",H25/G25-1) -> 0.14985114
A28: AI - historical only; valued as a residual vs. market cap on MAIN
A29: AI revenue | B29: $B | C29: 3.201
A30: no forecast - see MAIN reverse check
A32: CHECKS - FY2025A vs disclosed (every cell must read 0.000)
A33: Connectivity vs $11.387B | C33: =ROUND(C17-11.387,3) -> 0
A34: Space vs $4.086B | C34: =ROUND(C25-4.086,3) -> 0
A35: AI vs $3.201B | C35: =ROUND(C29-3.201,3) -> 0
A36: Consolidated vs $18.674B | C36: =ROUND(C17+C25+C29-18.674,3) -> 0
A38: LATEST ACTUALS - first half, $mm (10-Q, quarter ended June 30, 2026) | C38: 1H 2025 | D38: 1H 2026 | E38: Growth
A39: Connectivity - Consumer | C39: 3213 | D39: 4633 | E39: =D39/C39-1 -> 0.44195456
A40: Connectivity - Enterprise & Government | C40: 1849 | D40: 2915 | E40: =D40/C40-1 -> 0.57652785
A41: Connectivity total | C41: 5062 | D41: 7548 | E41: =D41/C41-1 -> 0.49111023
A42: Space - Launch Services | C42: 1056 | D42: 978 | E42: =D42/C42-1 -> -0.073863636
A43: Space - Launch & Development | C43: 555 | D43: 603 | E43: =D43/C43-1 -> 0.086486486
A44: Space total | C44: 1611 | D44: 1581 | E44: =D44/C44-1 -> -0.018621974
A45: AI total | C45: 1465 | D45: 3379 | E45: =D45/C45-1 -> 1.3064846
A46: Consolidated | C46: 8138 | D46: 12508 | E46: =D46/C46-1 -> 0.53698697
...

Sheet EBITDA Recon
A1: SPCX - FY2025A Segment EBITDA to EBIT Reconciliation
A2: All disclosed. Feeds the FY2025A anchor column on Assumptions. US$ billions.
A4: FY2025A | B4: Space | C4: Connectivity | D4: AI | E4: Total
A5: Segment revenue (from Revenue Build) | B5: ='Revenue Build'!C25 -> 4.086 | C5: ='Revenue Build'!C17 -> 11.387 | D5: ='Revenue Build'!C29 -> 3.201 | E5: =SUM(B5:D5) -> 18.674
A6: Income (loss) from operations | B6: -0.657 | C6: 4.423 | D6: -6.355 | E6: =SUM(B6:D6) -> -2.589
A7: Segment Adjusted EBITDA | B7: 0.653 | C7: 7.168 | D7: -1.237 | E7: =SUM(B7:D7) -> 6.584
A8: Total add-backs (EBITDA less EBIT) | B8: =B7-B6 -> 1.31 | C8: =C7-C6 -> 2.745 | D8: =D7-D6 -> 5.118 | E8: =SUM(B8:D8) -> 9.173
A9: of which: share-based comp (deck, rounded) | B9: 0.5 | C9: 0.4 | D9: 1.1 | E9: =SUM(B9:D9) -> 2
A10: of which: restructuring / impairment (deck, rounded) | B10: 0 | C10: 0 | D10: 0.5 | E10: =SUM(B10:D10) -> 0.5
A11: of which: D&A (derived residual) | B11: =B8-B9-B10 -> 0.81 | C11: =C8-C9-C10 -> 2.345 | D11: =D8-D9-D10 -> 3.518 | E11: =SUM(B11:D11) -> 6.673
A12: D&A per roadshow deck (rounded, for comparison) | B12: 0.8 | C12: 2.4 | D12: 3.6 | E12: =SUM(B12:D12) -> 6.8
A13: Rounding difference vs deck | B13: =B11-B12 -> 0.01 | C13: =C11-C12 -> -0.055 | D13: =D11-D12 -> -0.082
A15: Capital expenditures | B15: 3.832 | C15: 4.178 | D15: 12.727 | E15: =SUM(B15:D15) -> 20.737
A16: Starship R&D expensed within Space (memo) | B16: 3.004
A18: Derived ratios | B18: Space | C18: Connectivity | D18: AI | E18: Total
A19: Operating margin --> Assumptions FY2025A | B19: =B6/B5 -> -0.16079295 | C19: =C6/C5 -> 0.3884254 | D19: =D6/D5 -> -1.9853171 | E19: =E6/E5 -> -0.13864196
A20: Segment Adj. EBITDA margin | B20: =B7/B5 -> 0.159814 | C20: =C7/C5 -> 0.62948977 | D20: =D7/D5 -> -0.38644174 | E20: =E7/E5 -> 0.35257577
A21: D&A % of revenue --> Assumptions FY2025A | B21: =B11/B5 -> 0.19823789 | C21: =C11/C5 -> 0.20593659 | D21: =D11/D5 -> 1.0990316 | E21: =E11/E5 -> 0.35734176
A22: Share-based comp % of revenue | B22: =B9/B5 -> 0.12236907 | C22: =C9/C5 -> 0.035127777 | D22: =D9/D5 -> 0.34364261 | E22: =E9/E5 -> 0.10710078
A23: Capex % of revenue --> Assumptions FY2025A | B23: =B15/B5 -> 0.93783651 | C23: =C15/C5 -> 0.36690963 | D23: =D15/D5 -> 3.975945 | E23: =E15/E5 -> 1.1104745
A24: Space operating margin excluding Starship R&D (memo) | B24: =(B6+B16)/B5 -> 0.57440039
A26: Sources
A27: Segment revenue, operating income, Segment Adjusted EBITDA, capital expenditure and Starship research and development: Form 424(b)(4), 15 June 2026.
A28: Depreciation and share-based compensation split: free writing prospectus filed 12 June 2026 (accession 0001628280-26-040610), non-GAAP appendix; disclosed to $0.1B.
A29: Depreciation shown as the residual of Segment Adjusted EBITDA less operating income less share-based compensation and restructuring.

Sheet WACC
A1: SPCX - WACC Build
A2: Cost of equity via CAPM. Beta and exit multiple are segment-specific and follow the switch on the Assumptions tab.
A4: Risk-Free Rate (10Y UST) | B4: 0.0501
A5: Equity Risk Premium | B5: 0.05
A6: Levered Beta | B6: =CHOOSE(Assumptions!$C$3,Assumptions!C26,Assumptions!C34) -> 1.2
A7: Cost of Equity | B7: =IF(OR(B5="",B6=""),"",B4+B6*B5) -> 0.1101
A8: Pre-tax Cost of Debt | B8: 0.05855
A9: Tax Rate | B9: =IF(Assumptions!C12="","",Assumptions!C12) -> 0.2
A10: After-tax Cost of Debt | B10: =IF(B9="","",B8*(1-B9)) -> 0.04684
A11: Market Cap $B) | B11: =Assumptions!C17*Assumptions!C18 -> 2002.3567
A12: Gross Debt ($B) | B12: 39.364
A13: % Equity | B13: =B11/(B11+B12) -> 0.98072018
A14: % Debt | B14: =B12/(B11+B12) -> 0.019279816
A15: WACC | B15: =IF(OR(B7="",B10=""),"",(B7*B13)+(B10*B14)) -> 0.10888036

Sheet DCF
A1: SpaceX - Unlevered DCF
A3: US$ billions | B3: FY2025A | C3: FY2026E | D3: FY2027E | E3: FY2028E | F3: FY2029E | G3: FY2030E
A4: Revenue | B4: =Assumptions!C11 -> 11.387 | C4: =B4*(1+Assumptions!D5) -> 16.828 | D4: =C4*(1+Assumptions!E5) -> 23.214 | E4: =D4*(1+Assumptions!F5) -> 29.28 | F4: =E4*(1+Assumptions!G5) -> 34.6608 | G4: =F4*(1+Assumptions!H5) -> 39.6636
A5: y/y growth | C5: =Assumptions!D5 -> 0.47782559 | D5: =Assumptions!E5 -> 0.37948657 | E5: =Assumptions!F5 -> 0.26130783 | F5: =Assumptions!G5 -> 0.18377049 | G5: =Assumptions!H5 -> 0.14433596
A6: Operating Margin % | B6: =Assumptions!C6 -> 0.3884254 | C6: =Assumptions!D6 -> 0.38 | D6: =Assumptions!E6 -> 0.4 | E6: =Assumptions!F6 -> 0.42 | F6: =Assumptions!G6 -> 0.43 | G6: =Assumptions!H6 -> 0.44
A7: EBIT | B7: =B4*B6 -> 4.423 | C7: =C4*C6 -> 6.39464 | D7: =D4*D6 -> 9.2856 | E7: =E4*E6 -> 12.2976 | F7: =F4*F6 -> 14.904144 | G7: =G4*G6 -> 17.451984
A8: Effective Tax Rate | B8: =Assumptions!$C$12 -> 0.2 | C8: =Assumptions!$C$12 -> 0.2 | D8: =Assumptions!$C$12 -> 0.2 | E8: =Assumptions!$C$12 -> 0.2 | F8: =Assumptions!$C$12 -> 0.2 | G8: =Assumptions!$C$12 -> 0.2
A9: NOPAT | B9: =B7*(1-B8) -> 3.5384 | C9: =C7*(1-C8) -> 5.115712 | D9: =D7*(1-D8) -> 7.42848 | E9: =E7*(1-E8) -> 9.83808 | F9: =F7*(1-F8) -> 11.923315 | G9: =G7*(1-G8) -> 13.961587
A10: (+)D&A | B10: =B4*Assumptions!C8 -> 2.345 | C10: =C4*Assumptions!D8 -> 3.53388 | D10: =D4*Assumptions!E8 -> 4.99101 | E10: =E4*Assumptions!F8 -> 6.4416 | F10: =F4*Assumptions!G8 -> 7.625376 | G10: =G4*Assumptions!H8 -> 8.725992
A11: (-)CapEx | B11: =-B4*Assumptions!C7 -> -4.178 | C11: =-C4*Assumptions!D7 -> -6.39464 | D11: =-D4*Assumptions!E7 -> -7.89276 | E11: =-E4*Assumptions!F7 -> -8.784 | F11: =-F4*Assumptions!G7 -> -9.358416 | G11: =-G4*Assumptions!H7 -> -9.9159
A12: (-)Change in Working Capital | C12: =-Assumptions!$C$13*(C4-B4) -> -0.48969 | D12: =-Assumptions!$C$13*(D4-C4) -> -0.57474 | E12: =-Assumptions!$C$13*(E4-D4) -> -0.54594 | F12: =-Assumptions!$C$13*(F4-E4) -> -0.484272 | G12: =-Assumptions!$C$13*(G4-F4) -> -0.450252
A13: Free Cash Flow | B13: =B9+B10+B11 -> 1.7054 | C13: =C9+C10+C11+C12 -> 1.765262 | D13: =D9+D10+D11+D12 -> 3.95199 | E13: =E9+E10+E11+E12 -> 6.94974 | F13: =F9+F10+F11+F12 -> 9.7060032 | G13: =G9+G10+G11+G12 -> 12.321427
A15: Discount Period | C15: 1 | D15: =C15+1 -> 2 | E15: =D15+1 -> 3 | F15: =E15+1 -> 4 | G15: =F15+1 -> 5
A16: Discount Factor | C16: =1/(1+WACC!$B$15)^C15 -> 0.90181054 | D16: =1/(1+WACC!$B$15)^D15 -> 0.81326226 | E16: =1/(1+WACC!$B$15)^E15 -> 0.73340848 | F16: =1/(1+WACC!$B$15)^F15 -> 0.6613955 | G16: =1/(1+WACC!$B$15)^G15 -> 0.59645344
A17: PV of FCF | C17: =C13*C16 -> 1.5919319 | D17: =D13*D16 -> 3.2140043 | E17: =E13*E16 -> 5.0969982 | F17: =F13*F16 -> 6.4195068 | G17: =G13*G16 -> 7.3491576
A19: Valuation | C19: Perpetuity | E19: Exit Multiple
A20: Sum of PV of Explicit FCFs | C20: =SUM(C17:G17) -> 23.671599 | E20: =C20 -> 23.671599
A21: PV of terminal value | C21: =(G13*(1+Assumptions!$C$14)/(WACC!$B$15-Assumptions!$C$14))*G16 -> 89.80513 | E21: =((G7+G10)*Assumptions!$C$15)*G16 -> 93.683662
A22: Enterprise Value | C22: =C20+C21 -> 113.47673 | E22: =E20+E21 -> 117.35526
A23: (+) Net Cash | C23: =Assumptions!$C$16 -> 60.645 | E23: =Assumptions!$C$16 -> 60.645
A24: Equity Value | C24: =C22+C23 -> 174.12173 | E24: =E22+E23 -> 178.00026
A25: Diluted Shares | C25: =Assumptions!$C$17 -> 13.176 | E25: =Assumptions!$C$17 -> 13.176
A26: Implied Price per Share - Connectivity Only | C26: =C24/C25 -> 13.215067 | E26: =E24/E25 -> 13.509431
A27: Current Price | C27: =Assumptions!$C$18 -> 151.97 | E27: =Assumptions!$C$18 -> 151.97
A28: Upside/(Downside) | C28: =(C26/C27)-1 -> -0.9130416 | E28: =E26/E27-1 -> -0.91110462
A30: Method Reconciliation
A31: Perpetuity TV (undiscounted, $B) | C31: =G13*(1+Assumptions!$C$14)/(WACC!$B$15-Assumptions!$C$14) -> 150.5652
A32: Exit TV (undiscounted, $B) | C32: =(G7+G10)*Assumptions!$C$15 -> 157.06786
A33: Implied exit multiple (from term. g) | C33: =C31/(G7+G10) -> 5.7515982
A34: Implied terminal growth (from exit x) | C34: =(C32*WACC!$B$15-G13)/(G13+C32) -> 0.028220069
A36: Sensitivity - Selected Segment, Implied Price / Share
A37: WACC → / exit EV/EBITDA ↓ | C37: 0.09 | D37: 0.1 | E37: 0.11 | F37: 0.12 | G37: 0.13
B38: 4 | C38: {=(SUMPRODUCT($C$13:$G$13,1/(1+C$37)^(COLUMN($C$13:$G$13)-COLUMN($C$13)+1))+(($G$7+$G$10)*$B38)/(1+C$37)^5+Assumptions!$C$16)/Assumptions!$C$17} -> 11.680093 | D38: {=(SUMPRODUCT($C$13:$G$13,1/(1+D$37)^(COLUMN($C$13:$G$13)-COLUMN($C$13)+1))+(($G$7+$G$10)*$B38)/(1+D$37)^5+Assumptions!$C$16)/Assumptions!$C$17} -> 11.387003 | E38: {=(SUMPRODUCT($C$13:$G$13,1/(1+E$37)^(COLUMN($C$13:$G$13)-COLUMN($C$13)+1))+(($G$7+$G$10)*$B38)/(1+E$37)^5+Assumptions!$C$16)/Assumptions!$C$17} -> 11.108961 | F38: {=(SUMPRODUCT($C$13:$G$13,1/(1+F$37)^(COLUMN($C$13:$G$13)-COLUMN($C$13)+1))+(($G$7+$G$10)*$B38)/(1+F$37)^5+Assumptions!$C$16)/Assumptions!$C$17} -> 10.84506 | G38: {=(SUMPRODUCT($C$13:$G$13,1/(1+G$37)^(COLUMN($C$13:$G$13)-COLUMN($C$13)+1))+(($G$7+$G$10)*$B38)/(1+G$37)^5+Assumptions!$C$16)/Assumptions!$C$17} -> 10.594457
B39: 5 | C39: {=(SUMPRODUCT($C$13:$G$13,1/(1+C$37)^(COLUMN($C$13:$G$13)-COLUMN($C$13)+1))+(($G$7+$G$10)*$B39)/(1+C$37)^5+Assumptions!$C$16)/Assumptions!$C$17} -> 12.971372 | D39: {=(SUMPRODUCT($C$13:$G$13,1/(1+D$37)^(COLUMN($C$13:$G$13)-COLUMN($C$13)+1))+(($G$7+$G$10)*$B39)/(1+D$37)^5+Assumptions!$C$16)/Assumptions!$C$17} -> 12.620645 | E39: {=(SUMPRODUCT($C$13:$G$13,1/(1+E$37)^(COLUMN($C$13:$G$13)-COLUMN($C$13)+1))+(($G$7+$G$10)*$B39)/(1+E$37)^5+Assumptions!$C$16)/Assumptions!$C$17} -> 12.288026 | F39: {=(SUMPRODUCT($C$13:$G$13,1/(1+F$37)^(COLUMN($C$13:$G$13)-COLUMN($C$13)+1))+(($G$7+$G$10)*$B39)/(1+F$37)^5+Assumptions!$C$16)/Assumptions!$C$17} -> 11.972419 | G39: {=(SUMPRODUCT($C$13:$G$13,1/(1+G$37)^(COLUMN($C$13:$G$13)-COLUMN($C$13)+1))+(($G$7+$G$10)*$B39)/(1+G$37)^5+Assumptions!$C$16)/Assumptions!$C$17} -> 11.672808
B40: 6 | C40: {=(SUMPRODUCT($C$13:$G$13,1/(1+C$37)^(COLUMN($C$13:$G$13)-COLUMN($C$13)+1))+(($G$7+$G$10)*$B40)/(1+C$37)^5+Assumptions!$C$16)/Assumptions!$C$17} -> 14.26265 | D40: {=(SUMPRODUCT($C$13:$G$13,1/(1+D$37)^(COLUMN($C$13:$G$13)-COLUMN($C$13)+1))+(($G$7+$G$10)*$B40)/(1+D$37)^5+Assumptions!$C$16)/Assumptions!$C$17} -> 13.854287 | E40: {=(SUMPRODUCT($C$13:$G$13,1/(1+E$37)^(COLUMN($C$13:$G$13)-COLUMN($C$13)+1))+(($G$7+$G$10)*$B40)/(1+E$37)^5+Assumptions!$C$16)/Assumptions!$C$17} -> 13.46709 | F40: {=(SUMPRODUCT($C$13:$G$13,1/(1+F$37)^(COLUMN($C$13:$G$13)-COLUMN($C$13)+1))+(($G$7+$G$10)*$B40)/(1+F$37)^5+Assumptions!$C$16)/Assumptions!$C$17} -> 13.099779 | G40: {=(SUMPRODUCT($C$13:$G$13,1/(1+G$37)^(COLUMN($C$13:$G$13)-COLUMN($C$13)+1))+(($G$7+$G$10)*$B40)/(1+G$37)^5+Assumptions!$C$16)/Assumptions!$C$17} -> 12.751159
B41: 7 | C41: {=(SUMPRODUCT($C$13:$G$13,1/(1+C$37)^(COLUMN($C$13:$G$13)-COLUMN($C$13)+1))+(($G$7+$G$10)*$B41)/(1+C$37)^5+Assumptions!$C$16)/Assumptions!$C$17} -> 15.553929 | D41: {=(SUMPRODUCT($C$13:$G$13,1/(1+D$37)^(COLUMN($C$13:$G$13)-COLUMN($C$13)+1))+(($G$7+$G$10)*$B41)/(1+D$37)^5+Assumptions!$C$16)/Assumptions!$C$17} -> 15.087928 | E41: {=(SUMPRODUCT($C$13:$G$13,1/(1+E$37)^(COLUMN($C$13:$G$13)-COLUMN($C$13)+1))+(($G$7+$G$10)*$B41)/(1+E$37)^5+Assumptions!$C$16)/Assumptions!$C$17} -> 14.646155 | F41: {=(SUMPRODUCT($C$13:$G$13,1/(1+F$37)^(COLUMN($C$13:$G$13)-COLUMN($C$13)+1))+(($G$7+$G$10)*$B41)/(1+F$37)^5+Assumptions!$C$16)/Assumptions!$C$17} -> 14.227138 | G41: {=(SUMPRODUCT($C$13:$G$13,1/(1+G$37)^(COLUMN($C$13:$G$13)-COLUMN($C$13)+1))+(($G$7+$G$10)*$B41)/(1+G$37)^5+Assumptions!$C$16)/Assumptions!$C$17} -> 13.829511
B42: 8 | C42: {=(SUMPRODUCT($C$13:$G$13,1/(1+C$37)^(COLUMN($C$13:$G$13)-COLUMN($C$13)+1))+(($G$7+$G$10)*$B42)/(1+C$37)^5+Assumptions!$C$16)/Assumptions!$C$17} -> 16.845208 | D42: {=(SUMPRODUCT($C$13:$G$13,1/(1+D$37)^(COLUMN($C$13:$G$13)-COLUMN($C$13)+1))+(($G$7+$G$10)*$B42)/(1+D$37)^5+Assumptions!$C$16)/Assumptions!$C$17} -> 16.32157 | E42: {=(SUMPRODUCT($C$13:$G$13,1/(1+E$37)^(COLUMN($C$13:$G$13)-COLUMN($C$13)+1))+(($G$7+$G$10)*$B42)/(1+E$37)^5+Assumptions!$C$16)/Assumptions!$C$17} -> 15.825219 | F42: {=(SUMPRODUCT($C$13:$G$13,1/(1+F$37)^(COLUMN($C$13:$G$13)-COLUMN($C$13)+1))+(($G$7+$G$10)*$B42)/(1+F$37)^5+Assumptions!$C$16)/Assumptions!$C$17} -> 15.354497 | G42: {=(SUMPRODUCT($C$13:$G$13,1/(1+G$37)^(COLUMN($C$13:$G$13)-COLUMN($C$13)+1))+(($G$7+$G$10)*$B42)/(1+G$37)^5+Assumptions!$C$16)/Assumptions!$C$17} -> 14.907862
